<?xml version="1.0" encoding="UTF-8"?>
<!-- Generated by org.testng.reporters.JUnitReportReporter -->
<testsuite ignored="1" hostname="SZ-00343555-01" failures="1" tests="9" name="testcase.TestDemo" time="5.197" errors="1" timestamp="12 Aug 2022 09:00:17 GMT" skipped="0">
  <testcase classname="testcase.TestDemo" name="test" time="0.002"/>
  <testcase classname="testcase.TestDemo" name="test" time="0.002"/>
  <testcase classname="testcase.TestDemo" name="testHttpGet" time="1.159"/>
  <testcase classname="testcase.TestDemo" name="test1" time="0.003">
    <failure message="expected [2] but found [1]" type="java.lang.AssertionError">
      <![CDATA[java.lang.AssertionError: expected [2] but found [1]
	at org.testng.Assert.fail(Assert.java:94)
	at org.testng.Assert.failNotEquals(Assert.java:513)
	at org.testng.Assert.assertEqualsImpl(Assert.java:135)
	at org.testng.Assert.assertEquals(Assert.java:116)
	at org.testng.Assert.assertEquals(Assert.java:389)
	at org.testng.Assert.assertEquals(Assert.java:399)
	at testcase.TestDemo.test1(TestDemo.java:21)
	at java.base/jdk.internal.reflect.NativeMethodAccessorImpl.invoke0(Native Method)
	at java.base/jdk.internal.reflect.NativeMethodAccessorImpl.invoke(NativeMethodAccessorImpl.java:77)
	at java.base/jdk.internal.reflect.DelegatingMethodAccessorImpl.invoke(DelegatingMethodAccessorImpl.java:43)
	at java.base/java.lang.reflect.Method.invoke(Method.java:568)
	at org.testng.internal.MethodInvocationHelper.invokeMethod(MethodInvocationHelper.java:104)
	at org.testng.internal.Invoker.invokeMethod(Invoker.java:645)
	at org.testng.internal.Invoker.invokeTestMethod(Invoker.java:851)
	at org.testng.internal.Invoker.invokeTestMethods(Invoker.java:1177)
	at org.testng.internal.TestMethodWorker.invokeTestMethods(TestMethodWorker.java:129)
	at org.testng.internal.TestMethodWorker.run(TestMethodWorker.java:112)
	at org.testng.TestRunner.privateRun(TestRunner.java:756)
	at org.testng.TestRunner.run(TestRunner.java:610)
	at org.testng.SuiteRunner.runTest(SuiteRunner.java:387)
	at org.testng.SuiteRunner.runSequentially(SuiteRunner.java:382)
	at org.testng.SuiteRunner.privateRun(SuiteRunner.java:340)
	at org.testng.SuiteRunner.run(SuiteRunner.java:289)
	at org.testng.SuiteRunnerWorker.runSuite(SuiteRunnerWorker.java:52)
	at org.testng.SuiteRunnerWorker.run(SuiteRunnerWorker.java:86)
	at org.testng.TestNG.runSuitesSequentially(TestNG.java:1293)
	at org.testng.TestNG.runSuitesLocally(TestNG.java:1218)
	at org.testng.TestNG.runSuites(TestNG.java:1133)
	at org.testng.TestNG.run(TestNG.java:1104)
	at org.apache.maven.surefire.testng.TestNGExecutor.run(TestNGExecutor.java:283)
	at org.apache.maven.surefire.testng.TestNGXmlTestSuite.execute(TestNGXmlTestSuite.java:75)
	at org.apache.maven.surefire.testng.TestNGProvider.invoke(TestNGProvider.java:120)
	at org.apache.maven.surefire.booter.ForkedBooter.invokeProviderInSameClassLoader(ForkedBooter.java:384)
	at org.apache.maven.surefire.booter.ForkedBooter.runSuitesInProcess(ForkedBooter.java:345)
	at org.apache.maven.surefire.booter.ForkedBooter.execute(ForkedBooter.java:126)
	at org.apache.maven.surefire.booter.ForkedBooter.main(ForkedBooter.java:418)
]]>
    </failure>
  </testcase> <!-- test1 -->
  <testcase classname="testcase.TestDemo" name="testHttpPostMap" time="0.004"/>
  <testcase classname="testcase.TestDemo" name="testHttpPost" time="0.021"/>
  <testcase classname="testcase.TestDemo" name="test" time="0.003"/>
  <testcase classname="testcase.TestDemo" name="testTimeOut" time="3.012">
    <error message="Method testcase.TestDemo.testTimeOut() didn&#039;t finish within the time-out 3000" type="org.testng.internal.thread.ThreadTimeoutException">
      <![CDATA[org.testng.internal.thread.ThreadTimeoutException: Method testcase.TestDemo.testTimeOut() didn't finish within the time-out 3000
	at java.base@17.0.3.1/java.util.concurrent.FutureTask.set(FutureTask.java:229)
	at java.base@17.0.3.1/java.util.concurrent.FutureTask.run(FutureTask.java:272)
	at java.base@17.0.3.1/java.util.concurrent.ThreadPoolExecutor.runWorker(ThreadPoolExecutor.java:1136)
	at java.base@17.0.3.1/java.util.concurrent.ThreadPoolExecutor$Worker.run(ThreadPoolExecutor.java:635)
	at java.base@17.0.3.1/java.lang.Thread.run(Thread.java:833)
]]>
    </error>
  </testcase> <!-- testTimeOut -->
  <testcase classname="testcase.TestDemo" name="checkMapNotNull" time="0.991"/>
  <testcase classname="testcase.TestDemo" name="testOkHttpGet">
    <skipped/>
  </testcase> <!-- testOkHttpGet -->
</testsuite> <!-- testcase.TestDemo -->
